#VRML_SIM R2025a utf8

EXTERNPROTO "https://raw.githubusercontent.com/cyberbotics/webots/develop/projects/objects/backgrounds/protos/TexturedBackground.proto"
EXTERNPROTO "https://raw.githubusercontent.com/cyberbotics/webots/develop/projects/objects/backgrounds/protos/TexturedBackgroundLight.proto"
EXTERNPROTO "https://raw.githubusercontent.com/cyberbotics/webots/develop/projects/objects/floors/protos/Floor.proto"
EXTERNPROTO "https://raw.githubusercontent.com/cyberbotics/webots/develop/projects/appearances/protos/SandyGround.proto"
EXTERNPROTO "https://raw.githubusercontent.com/cyberbotics/webots/develop/projects/objects/road/protos/Road.proto"
EXTERNPROTO "https://raw.githubusercontent.com/cyberbotics/webots/develop/projects/appearances/protos/Pavement.proto"
EXTERNPROTO "https://raw.githubusercontent.com/cyberbotics/webots/develop/projects/objects/buildings/protos/Windmill.proto"
EXTERNPROTO "https://raw.githubusercontent.com/cyberbotics/webots/develop/projects/objects/buildings/protos/SmallManor.proto"
EXTERNPROTO "https://raw.githubusercontent.com/cyberbotics/webots/develop/projects/objects/factory/manhole/protos/SquareManhole.proto"
EXTERNPROTO "https://raw.githubusercontent.com/cyberbotics/webots/develop/projects/objects/factory/containers/protos/CardboardBox.proto"
EXTERNPROTO "https://raw.githubusercontent.com/cyberbotics/webots/develop/projects/vehicles/protos/tesla/TeslaModel3Simple.proto"
EXTERNPROTO "https://raw.githubusercontent.com/cyberbotics/webots/develop/projects/objects/trees/protos/Pine.proto"
EXTERNPROTO "https://raw.githubusercontent.com/cyberbotics/webots/develop/projects/objects/trees/protos/Forest.proto"
EXTERNPROTO "https://raw.githubusercontent.com/cyberbotics/webots/develop/projects/robots/dji/mavic/protos/Mavic2Pro.proto"
EXTERNPROTO "https://raw.githubusercontent.com/cyberbotics/webots/R2025a/projects/humans/pedestrian/protos/Pedestrian.proto"

WorldInfo {
  info [
    "This demonstration shows a DJI Mavic 2 PRO flying over a rural area by exposing the ROS2 Twist topic."
  ]
  title "ROS2 and DJI Mavic 2 PRO demo"
  basicTimeStep 8
  defaultDamping Damping {
    linear 0.5
    angular 0.5
  }
}
Viewpoint {
  orientation -0.09292479494503735 -0.0012064933613238063 0.9956723993654698 3.201100558705276
  position 8.8298891766877 1.02663147100698 2.6296900198889666
  near 0.2
  follow "Mavic 2 PRO"
  followSmoothness 0.2
}
TexturedBackground {
  luminosity 3
}
TexturedBackgroundLight {
}
Floor {
  size 400 400
  tileSize 6 6
  appearance SandyGround {
  }
}
Road {
  translation -43.8 9.2 0.01
  rotation 0 0 1 -0.39
  width 3
  numberOfLanes 1
  rightBorder FALSE
  leftBorder FALSE
  wayPoints [
    0 0 0
    100 0 0
    200 200 0
  ]
  splineSubdivision 8
  appearance Pavement {
    type "black stone"
  }
}
Windmill {
  translation -43.8656 -19.8433 0
  rotation 0 0 1 0.523601
}
Windmill {
  translation -44.258 -27.3356 0
  rotation 0 0 1 0.523601
  name "windmill(1)"
}
Windmill {
  translation -46.2448 30.573 0
  rotation 0 0 1 0.523601
  name "windmill(2)"
}
Windmill {
  translation -38.75 23.4 0
  name "windmill(3)"
}
SmallManor {
  translation -50.35 11.25 0
  rotation 0 0 1 -0.392394
}
SquareManhole {
  translation 0 0 -0.03
  rotation 0 0 1 -1.5707953071795862
}
CardboardBox {
  translation -0.730157 -1.22891 0.3
  rotation 0 0 1 1.309
}
TeslaModel3Simple {
  translation -41.5139 4.34169 0.31
  rotation 0 0 1 -0.2618053071795865
}
Pine {
  translation -14.0083 -14.4828 0
  rotation 0 0 1 3.1415853071795863
}
Pine {
  translation -19.6195 -24.3783 0
  rotation 0 0 1 3.14158
  name "pine tree(1)"
}
Pine {
  translation -22.0129 6.20205 0
  name "pine tree(3)"
}
Pine {
  translation -10.6926 -25.1339 0
  rotation 0 0 1 0.261797
  name "pine tree(4)"
}
Pine {
  translation -14.3441 14.5621 0
  name "pine tree(5)"
}
Pine {
  translation -26.6328 -7.1707 0
  name "pine tree(6)"
}
Pine {
  translation -9.37029 14.0209 0
  rotation 0 0 1 -2.6179953071795863
  name "pine tree(2)"
}
Forest {
  translation 0 0 -0.01
  shape [
    200 200
    200 0
    50 0
    50 50
    -50 50
    -50 -50
    50 -50
    50 0
    200 0
    200 -200
    -200 -200
    -200 200
  ]
  density 0.01
  type "cherry tree"
  randomSeed 1
  maxHeight 12
  minHeight 6
  maxRadius 6
  minRadius 3
}
Pedestrian {
  translation -16.41 0 1.27
}
Mavic2Pro {
  translation 0 0 0.1
  rotation 0 0 1 3.141590777218456
  name "Mavic_2_PRO"
  controller "<extern>"
  cameraSlot [
    Camera {
      width 400
      height 240
      near 0.2
    }
  ]
}
Robot {
  children [
    HingeJoint {
      jointParameters HingeJointParameters {
        axis 0 1 0
        anchor 0 0 0.025
      }
      device [
        RotationalMotor {
          name "left wheel motor"
        }
      ]
      endPoint Solid {
        translation 0 0.045 0.025
        rotation 0 1 0 0
        children [
          DEF WHEEL Pose {
            rotation 1 0 0 1.5707996938995747
            children [
              Shape {
                appearance PBRAppearance {
                  baseColor 1 0 0
                  roughness 1
                  metalness 0
                }
                geometry Cylinder {
                  height 0.01
                  radius 0.025
                }
              }
            ]
          }
        ]
        name "left wheel"
        boundingObject USE WHEEL
        physics Physics {
        }
      }
    }
    HingeJoint {
      jointParameters HingeJointParameters {
        axis 0 1 0
        anchor 0 0 0.025
      }
      device [
        RotationalMotor {
          name "right wheel motor"
        }
      ]
      endPoint Solid {
        translation 0 -0.045 0.025
        rotation 0 1 0 0
        children [
          USE WHEEL
        ]
        name "right wheel"
        boundingObject USE WHEEL
        physics Physics {
        }
      }
    }
    Pose {
      translation 0 0 0.0415
      children [
        Shape {
          appearance PBRAppearance {
            baseColor 0 0 1
            roughness 1
            metalness 0
          }
          geometry DEF BODY Cylinder {
            height 0.08
            radius 0.045
          }
        }
      ]
    }
    DistanceSensor {
      translation 0.042 0.02 0.063
      rotation 0 0 1 0.5236003061004253
      children [
        DEF SENSOR Pose {
          rotation 0 1 0 1.5708
          children [
            Shape {
              appearance PBRAppearance {
                baseColor 1 1 0
                roughness 1
                metalness 0
              }
              geometry Cylinder {
                height 0.004
                radius 0.008
              }
            }
          ]
        }
      ]
      name "ds0"
      lookupTable [
        0 1020 0
        0.05 1020 0
        0.15 0 0
      ]
      numberOfRays 2
      aperture 1
    }
    DistanceSensor {
      translation 0.042 -0.02 0.063
      rotation 0 0 1 -0.5235996938995747
      children [
        USE SENSOR
      ]
      name "ds1"
      lookupTable [
        0 1020 0
        0.05 1020 0
        0.15 0 0
      ]
      numberOfRays 2
      aperture 1
    }
  ]
  name "my_robot"
  boundingObject Pose {
    translation 0 0 0.0415
    children [
      USE BODY
    ]
  }
  physics Physics {
  }
  controller "<extern>"
}
Cat {
  translation 0.573639 -0.459616 0
  rotation 0 0 1 0.785398
}
